Workbook
Name a.csv_3: 'column function & word replace'!$A$1:$A$183
Name a.csv_3: Formulas!$A$1:$A$183
Name a.csv_3: MainTable!$A$1:$A$183
Name powerquery: 'powerQuery Table'!$G$20
Name Slicer_Continent: #N/A
Name Slicer_Development_Level: #N/A
Name Slicer_Unemployment_Level: #N/A
Name Slicer_Wage_Rating: #N/A

Sheet MainTable
A1: Country | B1: Continent | C1: Subregion | D1: Development Level | E1: Unemployment Level | F1: Population | G1: Monthly_wage(USD) | H1: Wage_Rating | I1: Average_Monthly_Salary(USD) | J1: Average_Salary_Rating | K1: Cost_of_Living_Rating | L1: Estimated Total Monthly Cost(USD) | M1: Inflation Rate (%)2025_2026 | N1: GDP_Nominal_USD_Billions_2025_IMF_Aligned
A2: Afghanistan | B2: Asia | C2: South Asia | D2: Least Developed | E2: Very High | F2: 42000000 | G2: 50 | H2: Very_Low_No_Enforced | I2: 90 | J2: Very_Low | K2: Very_Low | L2: 180 | M2: 10 | N2: 20
A3: Albania | B3: Europe | C3: Southern Europe | D3: Lower Developing | E3: High | F3: 2800000 | G3: 320 | H3: Medium | I3: 680 | J3: Low | K3: Low | L3: 520 | M3: 4 | N3: 28
A4: Algeria | B4: Africa | C4: North Africa | D4: Lower Developing | E4: High | F4: 46000000 | G4: 150 | H4: Low | I4: 520 | J4: Low | K4: Low | L4: 450 | M4: 5 | N4: 260
A5: American Samoa | B5: Oceania | C5: Polynesia | D5: Lower Developing | E5: High | F5: 50000 | G5: 1200 | H5: High | I5: 2900 | J5: High | K5: High | L5: 1800 | M5: 3 | N5: 1
A6: Andorra | B6: Europe | C6: Southern Europe | D6: Very High Developed | E6: Low | F6: 80000 | G6: 1600 | H6: Very_High | I6: 3200 | J6: High | K6: Very_High | L6: 2200 | M6: 3 | N6: 3
A7: Angola | B7: Africa | C7: Central Africa | D7: Least Developed | E7: Very High | F7: 36000000 | G7: 70 | H7: Very_Low_No_Enforced | I7: 210 | J7: Very_Low | K7: Low | L7: 500 | M7: 20 | N7: 115
A8: Anguilla | B8: North America | C8: Caribbean | D8: Lower Developing | E8: High | F8: 15000 | G8: 1000 | H8: High | I8: 2600 | J8: High | K8: High | L8: 2200 | M8: 3 | N8: 1
A9: Antigua & Barbuda | B9: North America | C9: Caribbean | D9: Upper Developing | E9: Moderate | F9: 100000 | G9: 600 | H9: Medium | I9: 1900 | J9: Medium | K9: High | L9: 2000 | M9: 4 | N9: 2
A10: Argentina | B10: South America | C10: South America | D10: Upper Developing | E10: Moderate | F10: 46000000 | G10: 200 | H10: Low | I10: 640 | J10: Low | K10: Medium | L10: 650 | M10: 30 | N10: 620
A11: Armenia | B11: Asia | C11: Western Asia | D11: Lower Developing | E11: High | F11: 3000000 | G11: 300 | H11: Medium | I11: 720 | J11: Low | K11: Low | L11: 500 | M11: 4 | N11: 28
A12: Aruba | B12: North America | C12: Caribbean | D12: Upper Developing | E12: Moderate | F12: 110000 | G12: 900 | H12: High | I12: 2400 | J12: High | K12: Very_High | L12: 2400 | M12: 4 | N12: 4
A13: Australia | B13: Oceania | C13: Australia & New Zealand | D13: Very High Developed | E13: Low | F13: 26000000 | G13: 2600 | H13: Very_High | I13: 5000 | J13: Very_High | K13: Very_High | L13: 2800 | M13: 3 | N13: 1800
... A130: Niger | B130: Africa | C130: West Africa | D130: Least Developed | E130: Very High | F130: 27000000 | G130: 50 | H130: Very_Low_No_Enforced | I130: 130 | J130: Very_Low | K130: Very_Low | L130: 200 | M130: 4 | N130: 18
A131: Nigeria | B131: Africa | C131: West Africa | D131: Lower Developing | E131: High | F131: 229000000 | G131: 50 | H131: Very_Low_No_Enforced | I131: 220 | J131: Very_Low | K131: Low | L131: 450 | M131: 24 | N131: 560 | R131: =F131/520000000 -> 0.44038462
A132: Norway | B132: Europe | C132: Northern Europe | D132: Very High Developed | E132: Low | F132: 5500000 | G132: 0 | H132: Very_High | I132: 5600 | J132: Very_High | K132: Very_High | L132: 3500 | M132: 3 | N132: 620
A133: Oman | B133: Asia | C133: Western Asia | D133: Very High Developed | E133: Low | F133: 5000000 | G133: 1100 | H133: High | I133: 3200 | J133: High | K133: Medium | L133: 2000 | M133: 2 | N133: 130
A134: Pakistan | B134: Asia | C134: South Asia | D134: Lower Developing | E134: High | F134: 242000000 | G134: 150 | H134: Low | I134: 360 | J134: Very_Low | K134: Very_Low | L134: 250 | M134: 30 | N134: 450
A135: Panama | B135: North America | C135: Central America | D135: Upper Developing | E135: Moderate | F135: 4400000 | G135: 700 | H135: High | I135: 1600 | J135: Medium | K135: Medium | L135: 1200 | M135: 3 | N135: 95
A136: Papua New Guinea | B136: Oceania | C136: Melanesia | D136: Least Developed | E136: Very High | F136: 10000000 | G136: 100 | H136: Very_Low_No_Enforced | I136: 260 | J136: Very_Low | K136: Very_Low | L136: 450 | M136: 5 | N136: 32
A137: Paraguay | B137: South America | C137: South America | D137: Lower Developing | E137: High | F137: 7200000 | G137: 300 | H137: Medium | I137: 720 | J137: Low | K137: Low | L137: 550 | M137: 4 | N137: 50
A138: Peru | B138: South America | C138: South America | D138: Upper Developing | E138: Moderate | F138: 34000000 | G138: 450 | H138: Medium | I138: 1050 | J138: Low | K138: Medium | L138: 750 | M138: 4 | N138: 250
A139: Philippines | B139: Asia | C139: Southeast Asia | D139: Lower Developing | E139: High | F139: 117000000 | G139: 180 | H139: Low | I139: 560 | J139: Very_Low | K139: Low | L139: 550 | M139: 5 | N139: 480
A140: Poland | B140: Europe | C140: Eastern Europe | D140: Very High Developed | E140: Low | F140: 37000000 | G140: 950 | H140: High | I140: 2300 | J140: Medium | K140: Medium | L140: 1600 | M140: 4 | N140: 820
A141: Portugal | B141: Europe | C141: Southern Europe | D141: Very High Developed | E141: Low | F141: 10200000 | G141: 1000 | H141: High | I141: 2200 | J141: Medium | K141: High | L141: 1900 | M141: 3 | N141: 310
A142: Qatar | B142: Asia | C142: Western Asia | D142: Very High Developed | E142: Low | F142: 3000000 | G142: 1600 | H142: Very_High | I142: 5000 | J142: Very_High | K142: High | L142: 2800 | M142: 2 | N142: 250
A143: Romania | B143: Europe | C143: Eastern Europe | D143: Very High Developed | E143: Low | F143: 19000000 | G143: 900 | H143: High | I143: 2000 | J143: Medium | K143: Medium | L143: 1400 | M143: 4 | N143: 360
... A183: Zimbabwe | B183: Africa | C183: Southern Africa | D183: Least Developed | E183: Very High | F183: 17000000 | G183: 100 | H183: Very_Low_No_Enforced | I183: 280 | J183: Very_Low | K183: Very_Low | L183: 250 | M183: 90 | N183: 32

Sheet column function & word replace
A1: Country | B1: Continent | C1: Subregion | D1: Development Level | E1: Unemployment Level | F1: Population | G1: Monthly_wage(USD) | H1: Wage Rating | I1: Average_Monthly_Salary(USD) | J1: Average Salary Rating | K1: Cost of Living Rating | L1: Estimated Total Monthly Cost(USD) | M1: Inflation Rate (%)2025_2026 | N1: GDP_Nominal(USD)
A2: Afghanistan | B2: Asia | C2: South Asia | D2: Least Developed | E2: Very High | F2: 42000000 | G2: 50 | H2: Very Low No Enforced | I2: 90 | J2: Very Low | K2: Very Low | L2: 180 | M2: 10 | N2: 20000000000
A3: Albania | B3: Europe | C3: Southern Europe | D3: Lower Developing | E3: High | F3: 2800000 | G3: 320 | H3: Medium | I3: 680 | J3: Low | K3: Low | L3: 520 | M3: 4 | N3: 28000000000
A4: Algeria | B4: Africa | C4: North Africa | D4: Lower Developing | E4: High | F4: 46000000 | G4: 150 | H4: Low | I4: 520 | J4: Low | K4: Low | L4: 450 | M4: 5 | N4: 260000000000
A5: American Samoa | B5: Oceania | C5: Polynesia | D5: Lower Developing | E5: High | F5: 50000 | G5: 1200 | H5: High | I5: 2900 | J5: High | K5: High | L5: 1800 | M5: 3 | N5: 1000000000
A6: Andorra | B6: Europe | C6: Southern Europe | D6: Very High Developed | E6: Low | F6: 80000 | G6: 1600 | H6: Very High | I6: 3200 | J6: High | K6: Very High | L6: 2200 | M6: 3 | N6: 3000000000
A7: Angola | B7: Africa | C7: Central Africa | D7: Least Developed | E7: Very High | F7: 36000000 | G7: 70 | H7: Very Low No Enforced | I7: 210 | J7: Very Low | K7: Low | L7: 500 | M7: 20 | N7: 115000000000
A8: Anguilla | B8: North America | C8: Caribbean | D8: Lower Developing | E8: High | F8: 15000 | G8: 1000 | H8: High | I8: 2600 | J8: High | K8: High | L8: 2200 | M8: 3 | N8: 1000000000
A9: Antigua & Barbuda | B9: North America | C9: Caribbean | D9: Upper Developing | E9: Moderate | F9: 100000 | G9: 600 | H9: Medium | I9: 1900 | J9: Medium | K9: High | L9: 2000 | M9: 4 | N9: 2000000000
A10: Argentina | B10: South America | C10: South America | D10: Upper Developing | E10: Moderate | F10: 46000000 | G10: 200 | H10: Low | I10: 640 | J10: Low | K10: Medium | L10: 650 | M10: 30 | N10: 620000000000
A11: Armenia | B11: Asia | C11: Western Asia | D11: Lower Developing | E11: High | F11: 3000000 | G11: 300 | H11: Medium | I11: 720 | J11: Low | K11: Low | L11: 500 | M11: 4 | N11: 28000000000
A12: Aruba | B12: North America | C12: Caribbean | D12: Upper Developing | E12: Moderate | F12: 110000 | G12: 900 | H12: High | I12: 2400 | J12: High | K12: Very High | L12: 2400 | M12: 4 | N12: 4000000000
A13: Australia | B13: Oceania | C13: Australia & New Zealand | D13: Very High Developed | E13: Low | F13: 26000000 | G13: 2600 | H13: Very High | I13: 5000 | J13: Very High | K13: Very High | L13: 2800 | M13: 3 | N13: 1800000000000
... A183: Zimbabwe | B183: Africa | C183: Southern Africa | D183: Least Developed | E183: Very High | F183: 17000000 | G183: 100 | H183: Very Low No Enforced | I183: 280 | J183: Very Low | K183: Very Low | L183: 250 | M183: 90 | N183: 32000000000

Sheet Formulas
A1: Country | B1: Continent | C1: Subregion | D1: Development Level | E1: Unemployment Level | F1: Population | G1: Monthly_wage(USD) | H1: Wage Rating | I1: Average_Monthly_Salary(USD) | J1: Average Salary Rating | K1: Cost of Living Rating | L1: Estimated Total Monthly Cost(USD) | M1: Inflation Rate (%)2025_2026 | N1: GDP_Nominal(USD) | O1: Disposable Income | P1: GDP per Capita
A2: Afghanistan | B2: Asia | C2: South Asia | D2: Least Developed | E2: Very High | F2: 42000000 | G2: 50 | H2: Very Low No Enforced | I2: 90 | J2: Very Low | K2: Very Low | L2: 180 | M2: 10 | N2: 20000000000 | O2: =I2-L2 -> -90 | P2: =N2/F2 -> 476.19048
A3: Albania | B3: Europe | C3: Southern Europe | D3: Lower Developing | E3: High | F3: 2800000 | G3: 320 | H3: Medium | I3: 680 | J3: Low | K3: Low | L3: 520 | M3: 4 | N3: 28000000000 | O3: =I3-L3 -> 160 | P3: =N3/F3 -> 10000
A4: Algeria | B4: Africa | C4: North Africa | D4: Lower Developing | E4: High | F4: 46000000 | G4: 150 | H4: Low | I4: 520 | J4: Low | K4: Low | L4: 450 | M4: 5 | N4: 260000000000 | O4: =I4-L4 -> 70 | P4: =N4/F4 -> 5652.1739
A5: American Samoa | B5: Oceania | C5: Polynesia | D5: Lower Developing | E5: High | F5: 50000 | G5: 1200 | H5: High | I5: 2900 | J5: High | K5: High | L5: 1800 | M5: 3 | N5: 1000000000 | O5: =I5-L5 -> 1100 | P5: =N5/F5 -> 20000
A6: Andorra | B6: Europe | C6: Southern Europe | D6: Very High Developed | E6: Low | F6: 80000 | G6: 1600 | H6: Very High | I6: 3200 | J6: High | K6: Very High | L6: 2200 | M6: 3 | N6: 3000000000 | O6: =I6-L6 -> 1000 | P6: =N6/F6 -> 37500
A7: Angola | B7: Africa | C7: Central Africa | D7: Least Developed | E7: Very High | F7: 36000000 | G7: 70 | H7: Very Low No Enforced | I7: 210 | J7: Very Low | K7: Low | L7: 500 | M7: 20 | N7: 115000000000 | O7: =I7-L7 -> -290 | P7: =N7/F7 -> 3194.4444
A8: Anguilla | B8: North America | C8: Caribbean | D8: Lower Developing | E8: High | F8: 15000 | G8: 1000 | H8: High | I8: 2600 | J8: High | K8: High | L8: 2200 | M8: 3 | N8: 1000000000 | O8: =I8-L8 -> 400 | P8: =N8/F8 -> 66666.667
A9: Antigua & Barbuda | B9: North America | C9: Caribbean | D9: Upper Developing | E9: Moderate | F9: 100000 | G9: 600 | H9: Medium | I9: 1900 | J9: Medium | K9: High | L9: 2000 | M9: 4 | N9: 2000000000 | O9: =I9-L9 -> -100 | P9: =N9/F9 -> 20000
A10: Argentina | B10: South America | C10: South America | D10: Upper Developing | E10: Moderate | F10: 46000000 | G10: 200 | H10: Low | I10: 640 | J10: Low | K10: Medium | L10: 650 | M10: 30 | N10: 620000000000 | O10: =I10-L10 -> -10 | P10: =N10/F10 -> 13478.261
A11: Armenia | B11: Asia | C11: Western Asia | D11: Lower Developing | E11: High | F11: 3000000 | G11: 300 | H11: Medium | I11: 720 | J11: Low | K11: Low | L11: 500 | M11: 4 | N11: 28000000000 | O11: =I11-L11 -> 220 | P11: =N11/F11 -> 9333.3333
A12: Aruba | B12: North America | C12: Caribbean | D12: Upper Developing | E12: Moderate | F12: 110000 | G12: 900 | H12: High | I12: 2400 | J12: High | K12: Very High | L12: 2400 | M12: 4 | N12: 4000000000 | O12: =I12-L12 -> 0 | P12: =N12/F12 -> 36363.636
A13: Australia | B13: Oceania | C13: Australia & New Zealand | D13: Very High Developed | E13: Low | F13: 26000000 | G13: 2600 | H13: Very High | I13: 5000 | J13: Very High | K13: Very High | L13: 2800 | M13: 3 | N13: 1800000000000 | O13: =I13-L13 -> 2200 | P13: =N13/F13 -> 69230.769
... A183: Zimbabwe | B183: Africa | C183: Southern Africa | D183: Least Developed | E183: Very High | F183: 17000000 | G183: 100 | H183: Very Low No Enforced | I183: 280 | J183: Very Low | K183: Very Low | L183: 250 | M183: 90 | N183: 32000000000 | O183: =I183-L183 -> 30 | P183: =N183/F183 -> 1882.3529

Sheet Table with filter
A1: Country | B1: Continent | C1: Subregion | D1: Development Level | E1: Unemployment Level | F1: Population | G1: Monthly_wage(USD) | H1: Wage Rating | I1: Average_Monthly_Salary(USD) | J1: Average Salary Rating | K1: Cost of Living Rating | L1: Estimated Total Monthly Cost(USD) | M1: Inflation Rate (%)2025_2026 | N1: GDP_Nominal(USD) | O1: Disposable Income | P1: GDP per Capita
A2: Afghanistan | B2: Asia | C2: South Asia | D2: Least Developed | E2: Very High | F2: 42000000 | G2: 50 | H2: Very Low | I2: 90 | J2: Very Low | K2: Very Low | L2: 180 | M2: 10 | N2: 20000000000 | O2: =I2-L2 -> -90 | P2: =N2/F2 -> 476.19048
A3: Albania | B3: Europe | C3: Southern Europe | D3: Lower Developing | E3: High | F3: 2800000 | G3: 320 | H3: Medium | I3: 680 | J3: Low | K3: Low | L3: 520 | M3: 4 | N3: 28000000000 | O3: =I3-L3 -> 160 | P3: =N3/F3 -> 10000
A4: Algeria | B4: Africa | C4: North Africa | D4: Lower Developing | E4: High | F4: 46000000 | G4: 150 | H4: Low | I4: 520 | J4: Low | K4: Low | L4: 450 | M4: 5 | N4: 260000000000 | O4: =I4-L4 -> 70 | P4: =N4/F4 -> 5652.1739
A5: American Samoa | B5: Oceania | C5: Polynesia | D5: Lower Developing | E5: High | F5: 50000 | G5: 1200 | H5: High | I5: 2900 | J5: High | K5: High | L5: 1800 | M5: 3 | N5: 1000000000 | O5: =I5-L5 -> 1100 | P5: =N5/F5 -> 20000
A6: Andorra | B6: Europe | C6: Southern Europe | D6: Very High Developed | E6: Low | F6: 80000 | G6: 1600 | H6: Very High | I6: 3200 | J6: High | K6: Very High | L6: 2200 | M6: 3 | N6: 3000000000 | O6: =I6-L6 -> 1000 | P6: =N6/F6 -> 37500
A7: Angola | B7: Africa | C7: Central Africa | D7: Least Developed | E7: Very High | F7: 36000000 | G7: 70 | H7: Very Low | I7: 210 | J7: Very Low | K7: Low | L7: 500 | M7: 20 | N7: 115000000000 | O7: =I7-L7 -> -290 | P7: =N7/F7 -> 3194.4444
A8: Anguilla | B8: North America | C8: Caribbean | D8: Lower Developing | E8: High | F8: 15000 | G8: 1000 | H8: High | I8: 2600 | J8: High | K8: High | L8: 2200 | M8: 3 | N8: 1000000000 | O8: =I8-L8 -> 400 | P8: =N8/F8 -> 66666.667
A9: Antigua & Barbuda | B9: North America | C9: Caribbean | D9: Upper Developing | E9: Moderate | F9: 100000 | G9: 600 | H9: Medium | I9: 1900 | J9: Medium | K9: High | L9: 2000 | M9: 4 | N9: 2000000000 | O9: =I9-L9 -> -100 | P9: =N9/F9 -> 20000
A10: Argentina | B10: South America | C10: South America | D10: Upper Developing | E10: Moderate | F10: 46000000 | G10: 200 | H10: Low | I10: 640 | J10: Low | K10: Medium | L10: 650 | M10: 30 | N10: 620000000000 | O10: =I10-L10 -> -10 | P10: =N10/F10 -> 13478.261
A11: Armenia | B11: Asia | C11: Western Asia | D11: Lower Developing | E11: High | F11: 3000000 | G11: 300 | H11: Medium | I11: 720 | J11: Low | K11: Low | L11: 500 | M11: 4 | N11: 28000000000 | O11: =I11-L11 -> 220 | P11: =N11/F11 -> 9333.3333
A12: Aruba | B12: North America | C12: Caribbean | D12: Upper Developing | E12: Moderate | F12: 110000 | G12: 900 | H12: High | I12: 2400 | J12: High | K12: Very High | L12: 2400 | M12: 4 | N12: 4000000000 | O12: =I12-L12 -> 0 | P12: =N12/F12 -> 36363.636
A13: Australia | B13: Oceania | C13: Australia & New Zealand | D13: Very High Developed | E13: Low | F13: 26000000 | G13: 2600 | H13: Very High | I13: 5000 | J13: Very High | K13: Very High | L13: 2800 | M13: 3 | N13: 1800000000000 | O13: =I13-L13 -> 2200 | P13: =N13/F13 -> 69230.769
... A183: Zimbabwe | B183: Africa | C183: Southern Africa | D183: Least Developed | E183: Very High | F183: 17000000 | G183: 100 | H183: Very Low | I183: 280 | J183: Very Low | K183: Very Low | L183: 250 | M183: 90 | N183: 32000000000 | O183: =I183-L183 -> 30 | P183: =N183/F183 -> 1882.3529

Sheet powerQuery Table
A1: Country | B1: Continent | C1: Subregion | D1: Development Level | E1: Unemployment Level | F1: Population | G1: Monthly_wage(USD) | H1: Wage Rating | I1: Average_Monthly_Salary(USD) | J1: Average Salary Rating | K1: Cost of Living Rating | L1: Estimated Total Monthly Cost(USD) | M1: Inflation Rate (%)2025_2026 | N1: GDP_Nominal(USD) | O1: Disposable Income | P1: GDP per Capita
A2: Afghanistan | B2: Asia | C2: South Asia | D2: Least Developed | E2: Very High | F2: 42000000 | G2: 50 | H2: Very Low | I2: 90 | J2: Very Low | K2: Very Low | L2: 180 | M2: 10 | N2: 20000000000 | O2: -90 | P2: 476.1905
A3: Albania | B3: Europe | C3: Southern Europe | D3: Lower Developing | E3: High | F3: 2800000 | G3: 320 | H3: Medium | I3: 680 | J3: Low | K3: Low | L3: 520 | M3: 4 | N3: 28000000000 | O3: 160 | P3: 10000
A4: Algeria | B4: Africa | C4: North Africa | D4: Lower Developing | E4: High | F4: 46000000 | G4: 150 | H4: Low | I4: 520 | J4: Low | K4: Low | L4: 450 | M4: 5 | N4: 260000000000 | O4: 70 | P4: 5652.1739
A5: American Samoa | B5: Oceania | C5: Polynesia | D5: Lower Developing | E5: High | F5: 50000 | G5: 1200 | H5: High | I5: 2900 | J5: High | K5: High | L5: 1800 | M5: 3 | N5: 1000000000 | O5: 1100 | P5: 20000
A6: Andorra | B6: Europe | C6: Southern Europe | D6: Very High Developed | E6: Low | F6: 80000 | G6: 1600 | H6: Very High | I6: 3200 | J6: High | K6: Very High | L6: 2200 | M6: 3 | N6: 3000000000 | O6: 1000 | P6: 37500
A7: Angola | B7: Africa | C7: Central Africa | D7: Least Developed | E7: Very High | F7: 36000000 | G7: 70 | H7: Very Low | I7: 210 | J7: Very Low | K7: Low | L7: 500 | M7: 20 | N7: 115000000000 | O7: -290 | P7: 3194.4444
A8: Anguilla | B8: North America | C8: Caribbean | D8: Lower Developing | E8: High | F8: 15000 | G8: 1000 | H8: High | I8: 2600 | J8: High | K8: High | L8: 2200 | M8: 3 | N8: 1000000000 | O8: 400 | P8: 66666.667
A9: Antigua & Barbuda | B9: North America | C9: Caribbean | D9: Upper Developing | E9: Moderate | F9: 100000 | G9: 600 | H9: Medium | I9: 1900 | J9: Medium | K9: High | L9: 2000 | M9: 4 | N9: 2000000000 | O9: -100 | P9: 20000
A10: Argentina | B10: South America | C10: South America | D10: Upper Developing | E10: Moderate | F10: 46000000 | G10: 200 | H10: Low | I10: 640 | J10: Low | K10: Medium | L10: 650 | M10: 30 | N10: 620000000000 | O10: -10 | P10: 13478.261
A11: Armenia | B11: Asia | C11: Western Asia | D11: Lower Developing | E11: High | F11: 3000000 | G11: 300 | H11: Medium | I11: 720 | J11: Low | K11: Low | L11: 500 | M11: 4 | N11: 28000000000 | O11: 220 | P11: 9333.3333
A12: Aruba | B12: North America | C12: Caribbean | D12: Upper Developing | E12: Moderate | F12: 110000 | G12: 900 | H12: High | I12: 2400 | J12: High | K12: Very High | L12: 2400 | M12: 4 | N12: 4000000000 | O12: 0 | P12: 36363.636
A13: Australia | B13: Oceania | C13: Australia & New Zealand | D13: Very High Developed | E13: Low | F13: 26000000 | G13: 2600 | H13: Very High | I13: 5000 | J13: Very High | K13: Very High | L13: 2800 | M13: 3 | N13: 1800000000000 | O13: 2200 | P13: 69230.769
... A183: Zimbabwe | B183: Africa | C183: Southern Africa | D183: Least Developed | E183: Very High | F183: 17000000 | G183: 100 | H183: Very Low | I183: 280 | J183: Very Low | K183: Very Low | L183: 250 | M183: 90 | N183: 32000000000 | O183: 30 | P183: 1882.3529

Sheet lookup_functions
A1: Vlookup | G1: Vlookup
A2: Countries | B2: Continent | C2: Sub-Region | G2: Countries | H2: Population
A3: Belgium | B3: =VLOOKUP(A3,'powerQuery Table'!A2:P183,2,FALSE) -> Europe | C3: =VLOOKUP(A3,'powerQuery Table'!A2:P183,3,FALSE) -> Western Europe | G3: Belgium | H3: =VLOOKUP(G3,'powerQuery Table'!A2:P183,6,FALSE) -> 11700000
A7: Vlookup With Data Validation(Drop Down
A8: Countries | B8: Continent | C8: Sub-Region
A9: Austria | B9: =VLOOKUP(A9,'powerQuery Table'!A2:P183,2,FALSE) -> Europe | C9: =VLOOKUP(A9,'powerQuery Table'!A2:P183,3,FALSE) -> Western Europe
A13: Lookup With The Row Details
A14: Country | B14: Continent | C14: Subregion | D14: Development Level | E14: Unemployment Level | F14: Population | G14: Monthly_wage(USD) | H14: Wage Rating | I14: Average_Monthly_Salary(USD) | J14: Average Salary Rating | K14: Cost of Living Rating | L14: Estimated Total Monthly Cost(USD) | M14: Inflation Rate (%)2025_2026 | N14: GDP_Nominal(USD) | O14: Disposable Income | P14: GDP per Capita
A15: Australia | B15: =LOOKUP($A$15,Table2[Country],Table2[Continent]) -> Oceania | C15: =LOOKUP($A$15,Table2[Country],Table2[Subregion]) -> Australia & New Zealand | D15: =LOOKUP(A15,Table2[Country],Table2[Development Level]) -> Very High Developed | E15: =LOOKUP(A15,Table2[Country],Table2[Unemployment Level]) -> Low | F15: =LOOKUP(A15,Table2[Country],Table2[Population]) -> 26000000 | G15: =LOOKUP(A15,Table2[Country],Table1[Monthly_wage(USD)]) -> 2600 | H15: =LOOKUP($A$15,Table2[Country],Table3[Wage Rating]) -> Very High | I15: =LOOKUP($A$15,Table2[Country],Table3[Average_Monthly_Salary(USD)]) -> 5000 | J15: =LOOKUP(A15,Table2[Country],Table3[Average Salary Rating]) -> Very High | K15: =LOOKUP(A15,Table2[Country],Table3[Cost of Living Rating]) -> Very High | L15: =LOOKUP(A15,Table2[Country],Table3[Estimated Total Monthly Cost(USD)]) -> 2800 | M15: =LOOKUP(A15,Table2[Country],Table3[Inflation Rate (%)2025_2026]) -> 3 | N15: =LOOKUP(A15,Table2[Country],Table3[GDP_Nominal(USD)]) -> 1800000000000 | O15: =LOOKUP(A15,Table2[Country],Table3[Disposable Income]) -> 2200 | P15: =LOOKUP(A15,Table2[Country],Table3[GDP per Capita]) -> 69230.769
A19: Index Match | E19: Match Function
A20: Serial Number | B20: Value | E20: Country | F20: Position Number
A21: 9 | B21: =INDEX(Table_Easy_sorting[Country],lookup_functions!A21) -> Argentina | E21: Argentina | F21: =MATCH(E21,Table2[Country],0) -> 9

Sheet Conditional_formatting
A1: Country | B1: Continent | C1: Subregion | D1: Development Level | E1: Unemployment Level | F1: Population | G1: Monthly_wage(USD) | H1: Wage Rating | I1: Average_Monthly_Salary(USD) | J1: Average Salary Rating | K1: Cost of Living Rating | L1: Estimated Total Monthly Cost(USD) | M1: Inflation Rate (%)2025_2026 | N1: GDP_Nominal(USD) | O1: Disposable Income | P1: GDP per Capita
A2: Australia | B2: Oceania | C2: Australia & New Zealand | D2: Very High Developed | E2: Low | F2: 26000000 | G2: 2600 | H2: Very High | I2: 5000 | J2: Very High | K2: Very High | L2: 2800 | M2: 3 | N2: 1800000000000 | O2: 2200 | P2: 69230.769
A3: Canada | B3: North America | C3: Northern America | D3: Very High Developed | E3: Low | F3: 41000000 | G3: 2200 | H3: Very High | I3: 4500 | J3: Very High | K3: Very High | L3: 3000 | M3: 3 | N3: 2300000000000 | O3: 1500 | P3: 56097.561
A4: Luxembourg | B4: Europe | C4: Western Europe | D4: Very High Developed | E4: Low | F4: 660000 | G4: 2200 | H4: Very High | I4: 6000 | J4: Very High | K4: Very High | L4: 3500 | M4: 3 | N4: 125000000000 | O4: 2500 | P4: 189393.94
A5: New Zealand | B5: Oceania | C5: Australia & New Zealand | D5: Very High Developed | E5: Low | F5: 5200000 | G5: 2200 | H5: Very High | I5: 4700 | J5: Very High | K5: Very High | L5: 3000 | M5: 3 | N5: 270000000000 | O5: 1700 | P5: 51923.077
A6: Germany | B6: Europe | C6: Western Europe | D6: Very High Developed | E6: Low | F6: 84000000 | G6: 2100 | H6: Very High | I6: 4300 | J6: Very High | K6: Very High | L6: 2900 | M6: 3 | N6: 4600000000000 | O6: 1400 | P6: 54761.905
A7: Belgium | B7: Europe | C7: Western Europe | D7: Very High Developed | E7: Low | F7: 11700000 | G7: 2000 | H7: Very High | I7: 3900 | J7: Very High | K7: Very High | L7: 2600 | M7: 3 | N7: 780000000000 | O7: 1300 | P7: 66666.667
A8: Ireland | B8: Europe | C8: Northern Europe | D8: Very High Developed | E8: Low | F8: 5300000 | G8: 2000 | H8: Very High | I8: 5200 | J8: Very High | K8: Very High | L8: 3000 | M8: 3 | N8: 720000000000 | O8: 2200 | P8: 135849.06
A9: Netherlands | B9: Europe | C9: Western Europe | D9: Very High Developed | E9: Low | F9: 17900000 | G9: 2000 | H9: Very High | I9: 4800 | J9: Very High | K9: Very High | L9: 3000 | M9: 3 | N9: 1120000000000 | O9: 1800 | P9: 62569.832
A10: United Kingdom | B10: Europe | C10: Northern Europe | D10: Very High Developed | E10: Low | F10: 68000000 | G10: 2000 | H10: Very High | I10: 4700 | J10: Very High | K10: Very High | L10: 3200 | M10: 3 | N10: 3100000000000 | O10: 1500 | P10: 45588.235
A11: Bermuda | B11: North America | C11: Caribbean | D11: Very High Developed | E11: Low | F11: 64000 | G11: 1800 | H11: Very High | I11: 5500 | J11: Very High | K11: Very High | L11: 3500 | M11: 3 | N11: 6000000000 | O11: 2000 | P11: 93750
A12: France | B12: Europe | C12: Western Europe | D12: Very High Developed | E12: Low | F12: 68000000 | G12: 1800 | H12: Very High | I12: 3600 | J12: Very High | K12: Very High | L12: 2800 | M12: 3 | N12: 3100000000000 | O12: 800 | P12: 45588.235
A13: Singapore | B13: Asia | C13: Southeast Asia | D13: Very High Developed | E13: Low | F13: 5900000 | G13: 1800 | H13: Very High | I13: 5500 | J13: Very High | K13: Very High | L13: 3500 | M13: 3 | N13: 540000000000 | O13: 2000 | P13: 91525.424
... A183: Western Sahara | B183: Africa | C183: North Africa | D183: Least Developed | E183: Very High | F183: 600000 | G183: 0 | H183: Very Low | I183: 0 | J183: Very Low | K183: Very Low | L183: 200 | M183: 4 | N183: 3000000000 | O183: -200 | P183: 5000

Sheet PivotTable
A1: AVG Population | B1: Average of Average_Monthly_Salary(USD) | C1: Average of Monthly_wage(USD) | D1: AVG GDP per Capita
A2: 43969368 | B2: 1587.3626 | C2: 501.7033 | D2: 23752.757
A5: Development Level | B5: Average of Monthly_wage(USD)
A6: High Developed | B6: 412.5
A7: Least Developed | B7: 73.928571
A8: Lower Developing | B8: 256.18644
A9: Upper Developing | B9: 475.65217
A10: Very High Developed | B10: 1120.3704
A14: Unemployment Level | B14: Sum of Population | C14: Count of Country
A15: High | B15: 3022167000 | C15: 59
A16: Low | B16: 1242048000 | C16: 54
A17: Moderate | B17: 2719110000 | C17: 27
A18: Very High | B18: 1019100000 | C18: 42
A23: Unemployment Level | B23: Sum of Average_Monthly_Salary(USD) | C23: Sum of Monthly_wage(USD) | D23: Sum of Population
A24: High | B24: 44900 | C24: 13100 | D24: 108425000
A25: Low | B25: 38430 | C25: 15365 | D25: 2928515000
A26: Medium | B26: 37200 | C26: 15700 | D26: 183230000
A27: Very High | B27: 148500 | C27: 39850 | D27: 996978000
A28: Very Low | B28: 19870 | C28: 7295 | D28: 3785277000
A33: Unemployment Level | B33: Sum of Population | C33: Sum of Monthly_wage(USD)
A34: High | B34: 3022167000 | C34: 15115
A35: Low | B35: 1242048000 | C35: 60500
A36: Moderate | B36: 2719110000 | C36: 12590
A37: Very High | B37: 1019100000 | C37: 3105
A44: Continent | B44: Average Population | C44: Average Monthly_wage(USD)
A45: Africa | B45: 28906000 | C45: 114.3
A46: Asia | B46: 98749375 | C46: 517.8125
A47: Europe | B47: 17935341 | C47: 800.4878
A48: North America | B48: 25036625 | C48: 705.625
A49: Oceania | B49: 6046714.3 | C49: 948.57143
A50: South America | B50: 36550000 | C50: 362.08333
A54: Continent | B54: Average of Estimated Total Monthly Cost(USD)
A55: Africa | B55: 360.4
A56: Asia | B56: 1062.5
A57: Europe | B57: 2143.1707
A58: North America | B58: 1540
A59: Oceania | B59: 1400
A60: South America | B60: 712.5
A66: Unemployment Level | B66: Count of Country
A67: High | B67: 59
...

Sheet Dashboard
C9: Continent | D9: AVG Estimated MC | F9: Unemployment Level | G9: Count Of Country
C10: =IF(A55=0," ",A55) -> Africa | D10: =IF(C10="Africa",B55,IF(C10="Asia",B55,IF(C10="Europe",B55,IF(C10="North America",B55,IF(C10="Oceania",B55,IF(C10="South America",B55," ")))))) -> 360.4 | F10: =IF(A63=0," ",A63) -> High | G10: =IF(F10="High",B63,IF(F10="Low",B64,IF(F10="Moderate",B65,IF(F10="Very High",B66," ")))) -> 59
C11: =IF(A56=0," ",A56) -> Asia | D11: =IF(C11="Africa",B56,IF(C11="Asia",B56,IF(C11="Europe",B56,IF(C11="North America",B56,IF(C11="Oceania",B56,IF(C11="South America",B56," ")))))) -> 1062.5 | F11: =IF(A64=0," ",A64) -> Low | G11: =IF(F11="High",B63,IF(F11="Low",B64,IF(F11="Moderate",B65,IF(F11="Very High",B66," ")))) -> 54
C12: =IF(A57=0," ",A57) -> Europe | D12: =IF(C12="Africa",B57,IF(C12="Asia",B57,IF(C12="Europe",B57,IF(C12="North America",B57,IF(C12="Oceania",B57,IF(C12="South America",B57," ")))))) -> 2143.1707 | F12: =IF(A65=0," ",A65) -> Moderate | G12: =IF(F12="High",B63,IF(F12="Low",B64,IF(F12="Moderate",B65,IF(F12="Very High",B66," ")))) -> 27
C13: =IF(A58=0," ",A58) -> North America | D13: =IF(C13="Africa",B58,IF(C13="Asia",B58,IF(C13="Europe",B58,IF(C13="North America",B58,IF(C13="Oceania",B58,IF(C13="South America",B58," ")))))) -> 1540 | F13: =IF(A66=0," ",A66) -> Very High | G13: =IF(F13="High",B63,IF(F13="Low",B64,IF(F13="Moderate",B65,IF(F13="Very High",B66," ")))) -> 42
C14: =IF(A59=0," ",A59) -> Oceania | D14: =IF(C14="Africa",B59,IF(C14="Asia",B59,IF(C14="Europe",B59,IF(C14="North America",B59,IF(C14="Oceania",B59,IF(C14="South America",B59," ")))))) -> 1400
C15: =IF(A60=0," ",A60) -> South America | D15: =IF(C15="Africa",B60,IF(C15="Asia",B60,IF(C15="Europe",B60,IF(C15="North America",B60,IF(C15="Oceania",B60,IF(C15="South America",B60," ")))))) -> 712.5
C16: Average Salary and GDP Per Capita By Sub-Region
A55: =PivotTable!A55 -> Africa | B55: =PivotTable!B55 -> 360.4
A56: =PivotTable!A56 -> Asia | B56: =PivotTable!B56 -> 1062.5
A57: =PivotTable!A57 -> Europe | B57: =PivotTable!B57 -> 2143.1707
A58: =PivotTable!A58 -> North America | B58: =PivotTable!B58 -> 1540
A59: =PivotTable!A59 -> Oceania | B59: =PivotTable!B59 -> 1400
A60: =PivotTable!A60 -> South America | B60: =GETPIVOTDATA("Estimated Total Monthly Cost(USD)",PivotTable!$A$54,"Continent","South America") -> 712.5
A63: =PivotTable!A67 -> High | B63: =PivotTable!B67 -> 59
A64: =PivotTable!A68 -> Low | B64: =PivotTable!B68 -> 54
A65: =PivotTable!A69 -> Moderate | B65: =PivotTable!B69 -> 27
A66: =PivotTable!A70 -> Very High | B66: =PivotTable!B70 -> 42
